<mujoco>
  <compiler inertiafromgeom="true" angle="degree" coordinate="local" />
  <option timestep="0.01" integrator="Euler"/>
  <default>
    <joint limited="false" armature="0" damping="0" />
    <geom conaffinity="1" contype="1" condim="1"  margin="0" friction="1 0.5 0.5" rgba="0.8 0.6 0.4 1" density="100" />
  </default>
  <asset>
    <texture type="skybox" builtin="gradient" width="100" height="100" rgb1="1 1 1" rgb2="0 0 0" />
    <texture name="texgeom" type="cube" builtin="flat" mark="cross" width="127" height="1278" rgb1="0.8 0.6 0.4" rgb2="0.8 0.6 0.4" markrgb="1 1 1" random="0.01" />
    <texture name="texplane" type="2d" builtin="checker" rgb1="0 0 0" rgb2="0.8 0.8 0.8" width="100" height="100" />
    <material name='geom' texture="texgeom" texuniform="true" />
    <material name='MatPlane' texture="marble2d"/>
    <material name='wall_tex' texture="darkwood"/>
    <material name='marble' texture="marble"/>
    <texture type="2d" name="marble" file="marble.png" />
    <texture type="2d" name="marble2d" file="light_wood_v3.png" />
    <texture type="2d" name="darkwood" file="darkwood.png" />
    <mesh name="mug" file="coffee_mug.stl" scale="8 8 8"/>
    <mesh name="gripperr" file="magnet.stl" scale="0.01 0.01 0.01"/>
  </asset>

  <worldbody>
    <light directional="true" cutoff="100" exponent="1" diffuse=".3 .3 .3" specular=".1 .1 .1" pos="0 0 1.3" dir="-0 0 -1.3" />
    <geom name='floor' material="MatPlane" pos='0 0 0' size='3.8 3.8 3' type='plane' conaffinity='1' rgba='1 1 1 1' condim='3' />
    <geom name='left_wall' material="wall_tex" pos='-3.8 0 0.2' size='0.1 3.8 0.2' type='box' conaffinity='1' rgba='1 0 0 1' condim='1' contype='1' />
    <geom name='right_wall' material="wall_tex"  pos='3.8 0 0.2' size='0.1 3.8 0.2' type='box' conaffinity='1' rgba='1 0 0 1' condim='1' contype='1' />
    <geom name='front_wall' material="wall_tex"  pos='0 3.8 0.2' size='3.8 0.1 0.2' type='box' conaffinity='1' rgba='1 0 0 1' condim='1' contype='1' />
    <geom name='back_wall'  material="wall_tex" pos='0 -3.8 0.2' size='3.8 0.1 0.2' type='box' conaffinity='1' rgba='1 0 0 1' condim='1' contype='1' />

    <body name="fist" pos="0 0 0">
      <!-- <geom name="pointbody" type="sphere" size="0.1" pos="0 0 0.1" /> -->
      <body name="gripper1" euler="0 0 90" pos="0.6 0 0" >
        <geom name="pointbodyr" type="mesh" euler="180 0 0" mesh="gripperr" size="0.1" pos="0 0 -0.1" rgba="0 0 0 1"/>
        <!-- <geom name="pointbodyr" type="mesh" euler="0 0 0" mesh="gripperr" size="0.1" pos="0 0 0.1" rgba="0 0 0 1"/>
        <geom name="pointbodyl" type="mesh" euler="0 180 0" mesh="gripperr" size="0.1" pos="1.3 0 0.1" rgba="0 0 0 1"/>
        <geom name='backplate' pos="0.6 0.85 0.1" size='0.4 0.2 0.04' type='box' rgba='0 0 0 1'/>
        <geom name='backplate2' pos="0.6 0.6 0.1" size='0.2 0.4 0.1' type='box' rgba='0 0 0 1'/>  -->
      </body>

      <joint name='ballx' type='slide' axis='1 0 0' pos='0 0 0'  limited="true" range="-3 3"/>
      <joint name='bally' type='slide' axis='0 1 0' pos='0 0 0'  limited="true" range="-3 3"/>
    </body>

    <body name="redcube" pos="0 0 0">
      <!-- <geom name="rc" type="box" size="0.2 0.2 0.2" pos="0 0 0.2" rgba="1 0 0 1" conaffinity="0" contype="0"/> -->
      <geom name="rc" type="mesh" mesh="mug" size="0.2 0.2 0.2" pos="0 0 0" conaffinity="0" contype="0"/>
      <joint name='rcx' type='slide' axis='1 0 0' pos='0 0 0' limited="true" range="-3 3"/>
      <joint name='rcy' type='slide' axis='0 1 0' pos='0 0 0' limited="true" range="-3 3"/>
    </body>

    <!-- <body name="bluecube" pos="0 0 0">
      <geom name="bc" type="box" size="0.2 0.2 0.2" pos="0 0 0.2" rgba="0 0 1 1" conaffinity="0" contype="0"/>
      <joint name='bcx' type='slide' axis='1 0 0' pos='0 0 0' />
      <joint name='bcy' type='slide' axis='0 1 0' pos='0 0 0' />
    </body>

    <body name="blacksphere" pos="0 0 0">
      <geom name="bs" type="sphere" size="0.2" pos="0 0 0.2" rgba="0 0 0 1" conaffinity="0" contype="0"/>
      <joint name='bsx' type='slide' axis='1 0 0' pos='0 0 0' />
      <joint name='bsy' type='slide' axis='0 1 0' pos='0 0 0' />
    </body>

    <body name="yellowcylinder" pos="0 0 0">
      <geom name="yc" type="cylinder" size="0.2 0.2" pos="0 0 0.2" rgba="1 1 0 1" conaffinity="0" contype="0"/>
      <joint name='ycx' type='slide' axis='1 0 0' pos='0 0 0' />
      <joint name='ycy' type='slide' axis='0 1 0' pos='0 0 0' />
    </body> -->

<!--     <geom name="tgt1" type="plane" size="0.2 0.2 0.01" pos="-2.5 -1 0.01" rgba="0 0 1 1"/>
    <geom name="tgt2" type="plane" size="0.2 0.2 0.01" pos="-2.5 1 0.01" rgba="0 0 0 1" />
    <geom name="tgt3" type="plane" size="0.2 0.2 0.01" pos="0 2 0.01" rgba="0.4 0.2 1 1"/>
    <geom name="tgt4" type="plane" size="0.2 0.2 0.01" pos="0 -2 0.01" rgba="1 0.3 0 1"/>
 -->

    <geom name="tgt1" material="marble" type="plane" size="0.2 0.2 0.03" pos="-2.5 -1 0.01" rgba="1 1 1 1" />
    <geom name="tgt1outer" type="box" size="0.25 0.25 0.001" pos="-2.5 -1 0.0" rgba="1 0 0 1"/>

    <geom name="tgt2" material="marble" type="plane" size="0.2 0.2 0.03" pos="-2.5 1 0.01" rgba="1 1 1 1" />
    <geom name="tgt2outer" type="box" size="0.25 0.25 0.001" pos="-2.5 1 0.0" rgba="0 1 0 1"/>

    <geom name="tgt3" material="marble" type="plane" size="0.2 0.2 0.03" pos="0 2 0.01" rgba="1 1 1 1" />
    <geom name="tgt3outer" type="box" size="0.25 0.25 0.001" pos="0 2 0.0" rgba="0 0 1 1"/>

    <geom name="tgt4" material="marble" type="plane" size="0.2 0.2 0.03" pos="0 -2 0.01" rgba="1 1 1 1" />
    <geom name="tgt4outer" type="box" size="0.25 0.25 0.001" pos="0 -2 0.0" rgba="0.5 0.5 0.5 1"/>

    <body name="random" pos="-10 -10 -10">
      <geom name="randombody" type="cylinder" size="0.2 0.2" pos="0 0 0.2" rgba="1 1 0 1" conaffinity="0" contype="0"/>
      <joint name='random_joint' type='slide' axis='0 1 0' pos='0 0 0' />
    </body>
    
    <site name='hand_goal' type="sphere" pos='0 0 -10' size='0.3' rgba='1 0 0 .3'/>
    <site name='obj_goal' type="sphere" pos='0 0 -10' size='0.3' rgba='0 1 0 .3'/>

    
    <site name="hand_1" pos="-0.49 0.46 0.15" size="0.11" rgba="0 0 1 1"/>
    <site name="hand_2" pos="-0.49 0.46 0.15" size="0.11" rgba="0 0 1 1"/>
    <site name="hand_3" pos="-0.49 0.46 0.15" size="0.11" rgba="0 0 1 1"/>
    <site name="hand_4" pos="-0.49 0.46 0.15" size="0.11" rgba="0 0 1 1"/>
    <site name="hand_5" pos="-0.49 0.46 0.15" size="0.11" rgba="0 0 1 1"/>
    <site name="hand_6" pos="-0.49 0.46 0.15" size="0.11" rgba="0 0 1 1"/>
    <site name="hand_7" pos="-0.49 0.46 0.15" size="0.11" rgba="0 0 1 1"/>
    <site name="hand_8" pos="-0.49 0.46 0.15" size="0.11" rgba="0 0 1 1"/>
    <site name="hand_9" pos="-0.49 0.46 0.15" size="0.11" rgba="0 0 1 1"/>
    <site name="hand_10" pos="-0.49 0.46 0.15" size="0.11" rgba="0 0 1 1"/>
    <site name="hand_11" pos="-0.49 0.46 0.15" size="0.11" rgba="0 0 1 1"/>
    <site name="hand_12" pos="-0.49 0.46 0.15" size="0.11" rgba="0 0 1 1"/>
    <site name="hand_13" pos="-0.49 0.46 0.15" size="0.11" rgba="0 0 1 1"/>
    <site name="hand_14" pos="-0.49 0.46 0.15" size="0.11" rgba="0 0 1 1"/>
    <site name="hand_15" pos="-0.49 0.46 0.15" size="0.11" rgba="0 0 1 1"/>
    <site name="hand_16" pos="-0.49 0.46 0.15" size="0.11" rgba="0 0 1 1"/>
    <site name="hand_17" pos="-0.49 0.46 0.15" size="0.11" rgba="0 0 1 1"/>
    <site name="hand_18" pos="-0.49 0.46 0.15" size="0.11" rgba="0 0 1 1"/>
    <site name="hand_19" pos="-0.49 0.46 0.15" size="0.11" rgba="0 0 1 1"/>
    <site name="hand_20" pos="-0.49 0.46 0.15" size="0.11" rgba="0 0 1 1"/>
    <site name="hand_21" pos="-0.49 0.46 0.15" size="0.11" rgba="0 0 1 1"/>
    <site name="hand_22" pos="-0.49 0.46 0.15" size="0.11" rgba="0 0 1 1"/>
    <site name="hand_23" pos="-0.49 0.46 0.15" size="0.11" rgba="0 0 1 1"/>
    <site name="hand_24" pos="-0.49 0.46 0.15" size="0.11" rgba="0 0 1 1"/>
    <site name="hand_25" pos="-0.49 0.46 0.15" size="0.11" rgba="0 0 1 1"/>
    <site name="hand_26" pos="-0.49 0.46 0.15" size="0.11" rgba="0 0 1 1"/>
    <site name="hand_27" pos="-0.49 0.46 0.15" size="0.11" rgba="0 0 1 1"/>
    <site name="hand_28" pos="-0.49 0.46 0.15" size="0.11" rgba="0 0 1 1"/>
    <site name="hand_29" pos="-0.49 0.46 0.15" size="0.11" rgba="0 0 1 1"/>
    <site name="hand_30" pos="-0.49 0.46 0.15" size="0.11" rgba="0 0 1 1"/>
    <site name="hand_31" pos="-0.49 0.46 0.15" size="0.11" rgba="0 0 1 1"/>
    <site name="hand_32" pos="-0.49 0.46 0.15" size="0.11" rgba="0 0 1 1"/>
    <site name="hand_33" pos="-0.49 0.46 0.15" size="0.11" rgba="0 0 1 1"/>
    <site name="hand_34" pos="-0.49 0.46 0.15" size="0.11" rgba="0 0 1 1"/>
    <site name="hand_35" pos="-0.49 0.46 0.15" size="0.11" rgba="0 0 1 1"/>
    <site name="hand_36" pos="-0.49 0.46 0.15" size="0.11" rgba="0 0 1 1"/>
    <site name="hand_37" pos="-0.49 0.46 0.15" size="0.11" rgba="0 0 1 1"/>
    <site name="hand_38" pos="-0.49 0.46 0.15" size="0.11" rgba="0 0 1 1"/>
    <site name="hand_39" pos="-0.49 0.46 0.15" size="0.11" rgba="0 0 1 1"/>
    <site name="hand_40" pos="-0.49 0.46 0.15" size="0.11" rgba="0 0 1 1"/>
    <site name="hand_41" pos="-0.49 0.46 0.15" size="0.11" rgba="0 0 1 1"/>
    <site name="hand_42" pos="-0.49 0.46 0.15" size="0.11" rgba="0 0 1 1"/>
    <site name="hand_43" pos="-0.49 0.46 0.15" size="0.11" rgba="0 0 1 1"/>
    <site name="hand_44" pos="-0.49 0.46 0.15" size="0.11" rgba="0 0 1 1"/>
    <site name="hand_45" pos="-0.49 0.46 0.15" size="0.11" rgba="0 0 1 1"/>
    <site name="hand_46" pos="-0.49 0.46 0.15" size="0.11" rgba="0 0 1 1"/>
    <site name="hand_47" pos="-0.49 0.46 0.15" size="0.11" rgba="0 0 1 1"/>
    <site name="hand_48" pos="-0.49 0.46 0.15" size="0.11" rgba="0 0 1 1"/>
    <site name="hand_49" pos="-0.49 0.46 0.15" size="0.11" rgba="0 0 1 1"/>
    <site name="hand_50" pos="-0.49 0.46 0.15" size="0.11" rgba="0 0 1 1"/>
    <!-- <site name="hand_51" pos="-0.49 0.46 0.15" size="0.11" rgba="0 0 1 1"/>
    <site name="hand_52" pos="-0.49 0.46 0.15" size="0.11" rgba="0 0 1 1"/>
    <site name="hand_53" pos="-0.49 0.46 0.15" size="0.11" rgba="0 0 1 1"/>
    <site name="hand_54" pos="-0.49 0.46 0.15" size="0.11" rgba="0 0 1 1"/>
    <site name="hand_55" pos="-0.49 0.46 0.15" size="0.11" rgba="0 0 1 1"/>
    <site name="hand_56" pos="-0.49 0.46 0.15" size="0.11" rgba="0 0 1 1"/>
    <site name="hand_57" pos="-0.49 0.46 0.15" size="0.11" rgba="0 0 1 1"/>
    <site name="hand_58" pos="-0.49 0.46 0.15" size="0.11" rgba="0 0 1 1"/>
    <site name="hand_59" pos="-0.49 0.46 0.15" size="0.11" rgba="0 0 1 1"/>
    <site name="hand_60" pos="-0.49 0.46 0.15" size="0.11" rgba="0 0 1 1"/>
    <site name="hand_61" pos="-0.49 0.46 0.15" size="0.11" rgba="0 0 1 1"/>
    <site name="hand_62" pos="-0.49 0.46 0.15" size="0.11" rgba="0 0 1 1"/>
    <site name="hand_63" pos="-0.49 0.46 0.15" size="0.11" rgba="0 0 1 1"/>
    <site name="hand_64" pos="-0.49 0.46 0.15" size="0.11" rgba="0 0 1 1"/>
    <site name="hand_65" pos="-0.49 0.46 0.15" size="0.11" rgba="0 0 1 1"/>
    <site name="hand_66" pos="-0.49 0.46 0.15" size="0.11" rgba="0 0 1 1"/>
    <site name="hand_67" pos="-0.49 0.46 0.15" size="0.11" rgba="0 0 1 1"/>
    <site name="hand_68" pos="-0.49 0.46 0.15" size="0.11" rgba="0 0 1 1"/>
    <site name="hand_69" pos="-0.49 0.46 0.15" size="0.11" rgba="0 0 1 1"/>
    <site name="hand_70" pos="-0.49 0.46 0.15" size="0.11" rgba="0 0 1 1"/>
    <site name="hand_71" pos="-0.49 0.46 0.15" size="0.11" rgba="0 0 1 1"/>
    <site name="hand_72" pos="-0.49 0.46 0.15" size="0.11" rgba="0 0 1 1"/>
    <site name="hand_73" pos="-0.49 0.46 0.15" size="0.11" rgba="0 0 1 1"/>
    <site name="hand_74" pos="-0.49 0.46 0.15" size="0.11" rgba="0 0 1 1"/>
    <site name="hand_75" pos="-0.49 0.46 0.15" size="0.11" rgba="0 0 1 1"/>
    <site name="hand_76" pos="-0.49 0.46 0.15" size="0.11" rgba="0 0 1 1"/>
    <site name="hand_77" pos="-0.49 0.46 0.15" size="0.11" rgba="0 0 1 1"/>
    <site name="hand_78" pos="-0.49 0.46 0.15" size="0.11" rgba="0 0 1 1"/>
    <site name="hand_79" pos="-0.49 0.46 0.15" size="0.11" rgba="0 0 1 1"/>
    <site name="hand_80" pos="-0.49 0.46 0.15" size="0.11" rgba="0 0 1 1"/>    
    <site name="hand_81" pos="-0.49 0.46 0.15" size="0.11" rgba="0 0 1 1"/>
    <site name="hand_82" pos="-0.49 0.46 0.15" size="0.11" rgba="0 0 1 1"/>
    <site name="hand_83" pos="-0.49 0.46 0.15" size="0.11" rgba="0 0 1 1"/>
    <site name="hand_84" pos="-0.49 0.46 0.15" size="0.11" rgba="0 0 1 1"/>
    <site name="hand_85" pos="-0.49 0.46 0.15" size="0.11" rgba="0 0 1 1"/>
    <site name="hand_86" pos="-0.49 0.46 0.15" size="0.11" rgba="0 0 1 1"/>
    <site name="hand_87" pos="-0.49 0.46 0.15" size="0.11" rgba="0 0 1 1"/>
    <site name="hand_88" pos="-0.49 0.46 0.15" size="0.11" rgba="0 0 1 1"/>
    <site name="hand_89" pos="-0.49 0.46 0.15" size="0.11" rgba="0 0 1 1"/>
    <site name="hand_90" pos="-0.49 0.46 0.15" size="0.11" rgba="0 0 1 1"/>    
    <site name="hand_91" pos="-0.49 0.46 0.15" size="0.11" rgba="0 0 1 1"/>
    <site name="hand_92" pos="-0.49 0.46 0.15" size="0.11" rgba="0 0 1 1"/>
    <site name="hand_93" pos="-0.49 0.46 0.15" size="0.11" rgba="0 0 1 1"/>
    <site name="hand_94" pos="-0.49 0.46 0.15" size="0.11" rgba="0 0 1 1"/>
    <site name="hand_95" pos="-0.49 0.46 0.15" size="0.11" rgba="0 0 1 1"/>
    <site name="hand_96" pos="-0.49 0.46 0.15" size="0.11" rgba="0 0 1 1"/>
    <site name="hand_97" pos="-0.49 0.46 0.15" size="0.11" rgba="0 0 1 1"/>
    <site name="hand_98" pos="-0.49 0.46 0.15" size="0.11" rgba="0 0 1 1"/>
    <site name="hand_99" pos="-0.49 0.46 0.15" size="0.11" rgba="0 0 1 1"/>
    <site name="hand_100" pos="-0.49 0.46 0.15" size="0.11" rgba="0 0 1 1"/> -->

    <site name="obj_1" pos="-0.49 0.46 0.15" size="0.11" rgba="1 0 0 1"/>
    <site name="obj_2" pos="-0.49 0.46 0.15" size="0.11" rgba="1 0 0 1"/>
    <site name="obj_3" pos="-0.49 0.46 0.15" size="0.11" rgba="1 0 0 1"/>
    <site name="obj_4" pos="-0.49 0.46 0.15" size="0.11" rgba="1 0 0 1"/>
    <site name="obj_5" pos="-0.49 0.46 0.15" size="0.11" rgba="1 0 0 1"/>
    <site name="obj_6" pos="-0.49 0.46 0.15" size="0.11" rgba="1 0 0 1"/>
    <site name="obj_7" pos="-0.49 0.46 0.15" size="0.11" rgba="1 0 0 1"/>
    <site name="obj_8" pos="-0.49 0.46 0.15" size="0.11" rgba="1 0 0 1"/>
    <site name="obj_9" pos="-0.49 0.46 0.15" size="0.11" rgba="1 0 0 1"/>
    <site name="obj_10" pos="-0.49 0.46 0.15" size="0.11" rgba="1 0 0 1"/>
    <site name="obj_11" pos="-0.49 0.46 0.15" size="0.11" rgba="1 0 0 1"/>
    <site name="obj_12" pos="-0.49 0.46 0.15" size="0.11" rgba="1 0 0 1"/>
    <site name="obj_13" pos="-0.49 0.46 0.15" size="0.11" rgba="1 0 0 1"/>
    <site name="obj_14" pos="-0.49 0.46 0.15" size="0.11" rgba="1 0 0 1"/>
    <site name="obj_15" pos="-0.49 0.46 0.15" size="0.11" rgba="1 0 0 1"/>
    <site name="obj_16" pos="-0.49 0.46 0.15" size="0.11" rgba="1 0 0 1"/>
    <site name="obj_17" pos="-0.49 0.46 0.15" size="0.11" rgba="1 0 0 1"/>
    <site name="obj_18" pos="-0.49 0.46 0.15" size="0.11" rgba="1 0 0 1"/>
    <site name="obj_19" pos="-0.49 0.46 0.15" size="0.11" rgba="1 0 0 1"/>
    <site name="obj_20" pos="-0.49 0.46 0.15" size="0.11" rgba="1 0 0 1"/>
    <site name="obj_21" pos="-0.49 0.46 0.15" size="0.11" rgba="1 0 0 1"/>
    <site name="obj_22" pos="-0.49 0.46 0.15" size="0.11" rgba="1 0 0 1"/>
    <site name="obj_23" pos="-0.49 0.46 0.15" size="0.11" rgba="1 0 0 1"/>
    <site name="obj_24" pos="-0.49 0.46 0.15" size="0.11" rgba="1 0 0 1"/>
    <site name="obj_25" pos="-0.49 0.46 0.15" size="0.11" rgba="1 0 0 1"/>
    <site name="obj_26" pos="-0.49 0.46 0.15" size="0.11" rgba="1 0 0 1"/>
    <site name="obj_27" pos="-0.49 0.46 0.15" size="0.11" rgba="1 0 0 1"/>
    <site name="obj_28" pos="-0.49 0.46 0.15" size="0.11" rgba="1 0 0 1"/>
    <site name="obj_29" pos="-0.49 0.46 0.15" size="0.11" rgba="1 0 0 1"/>
    <site name="obj_30" pos="-0.49 0.46 0.15" size="0.11" rgba="1 0 0 1"/>
    <site name="obj_31" pos="-0.49 0.46 0.15" size="0.11" rgba="1 0 0 1"/>
    <site name="obj_32" pos="-0.49 0.46 0.15" size="0.11" rgba="1 0 0 1"/>
    <site name="obj_33" pos="-0.49 0.46 0.15" size="0.11" rgba="1 0 0 1"/>
    <site name="obj_34" pos="-0.49 0.46 0.15" size="0.11" rgba="1 0 0 1"/>
    <site name="obj_35" pos="-0.49 0.46 0.15" size="0.11" rgba="1 0 0 1"/>
    <site name="obj_36" pos="-0.49 0.46 0.15" size="0.11" rgba="1 0 0 1"/>
    <site name="obj_37" pos="-0.49 0.46 0.15" size="0.11" rgba="1 0 0 1"/>
    <site name="obj_38" pos="-0.49 0.46 0.15" size="0.11" rgba="1 0 0 1"/>
    <site name="obj_39" pos="-0.49 0.46 0.15" size="0.11" rgba="1 0 0 1"/>
    <site name="obj_40" pos="-0.49 0.46 0.15" size="0.11" rgba="1 0 0 1"/>
    <site name="obj_41" pos="-0.49 0.46 0.15" size="0.11" rgba="1 0 0 1"/>
    <site name="obj_42" pos="-0.49 0.46 0.15" size="0.11" rgba="1 0 0 1"/>
    <site name="obj_43" pos="-0.49 0.46 0.15" size="0.11" rgba="1 0 0 1"/>
    <site name="obj_44" pos="-0.49 0.46 0.15" size="0.11" rgba="1 0 0 1"/>
    <site name="obj_45" pos="-0.49 0.46 0.15" size="0.11" rgba="1 0 0 1"/>
    <site name="obj_46" pos="-0.49 0.46 0.15" size="0.11" rgba="1 0 0 1"/>
    <site name="obj_47" pos="-0.49 0.46 0.15" size="0.11" rgba="1 0 0 1"/>
    <site name="obj_48" pos="-0.49 0.46 0.15" size="0.11" rgba="1 0 0 1"/>
    <site name="obj_49" pos="-0.49 0.46 0.15" size="0.11" rgba="1 0 0 1"/>
    <site name="obj_50" pos="-0.49 0.46 0.15" size="0.11" rgba="1 0 0 1"/>
    <!-- <site name="obj_51" pos="-0.49 0.46 0.15" size="0.11" rgba="1 0 0 1"/>
    <site name="obj_52" pos="-0.49 0.46 0.15" size="0.11" rgba="1 0 0 1"/>
    <site name="obj_53" pos="-0.49 0.46 0.15" size="0.11" rgba="1 0 0 1"/>
    <site name="obj_54" pos="-0.49 0.46 0.15" size="0.11" rgba="1 0 0 1"/>
    <site name="obj_55" pos="-0.49 0.46 0.15" size="0.11" rgba="1 0 0 1"/>
    <site name="obj_56" pos="-0.49 0.46 0.15" size="0.11" rgba="1 0 0 1"/>
    <site name="obj_57" pos="-0.49 0.46 0.15" size="0.11" rgba="1 0 0 1"/>
    <site name="obj_58" pos="-0.49 0.46 0.15" size="0.11" rgba="1 0 0 1"/>
    <site name="obj_59" pos="-0.49 0.46 0.15" size="0.11" rgba="1 0 0 1"/>
    <site name="obj_60" pos="-0.49 0.46 0.15" size="0.11" rgba="1 0 0 1"/>
    <site name="obj_61" pos="-0.49 0.46 0.15" size="0.11" rgba="1 0 0 1"/>
    <site name="obj_62" pos="-0.49 0.46 0.15" size="0.11" rgba="1 0 0 1"/>
    <site name="obj_63" pos="-0.49 0.46 0.15" size="0.11" rgba="1 0 0 1"/>
    <site name="obj_64" pos="-0.49 0.46 0.15" size="0.11" rgba="1 0 0 1"/>
    <site name="obj_65" pos="-0.49 0.46 0.15" size="0.11" rgba="1 0 0 1"/>
    <site name="obj_66" pos="-0.49 0.46 0.15" size="0.11" rgba="1 0 0 1"/>
    <site name="obj_67" pos="-0.49 0.46 0.15" size="0.11" rgba="1 0 0 1"/>
    <site name="obj_68" pos="-0.49 0.46 0.15" size="0.11" rgba="1 0 0 1"/>
    <site name="obj_69" pos="-0.49 0.46 0.15" size="0.11" rgba="1 0 0 1"/>
    <site name="obj_70" pos="-0.49 0.46 0.15" size="0.11" rgba="1 0 0 1"/>
    <site name="obj_71" pos="-0.49 0.46 0.15" size="0.11" rgba="1 0 0 1"/>
    <site name="obj_72" pos="-0.49 0.46 0.15" size="0.11" rgba="1 0 0 1"/>
    <site name="obj_73" pos="-0.49 0.46 0.15" size="0.11" rgba="1 0 0 1"/>
    <site name="obj_74" pos="-0.49 0.46 0.15" size="0.11" rgba="1 0 0 1"/>
    <site name="obj_75" pos="-0.49 0.46 0.15" size="0.11" rgba="1 0 0 1"/>
    <site name="obj_76" pos="-0.49 0.46 0.15" size="0.11" rgba="1 0 0 1"/>
    <site name="obj_77" pos="-0.49 0.46 0.15" size="0.11" rgba="1 0 0 1"/>
    <site name="obj_78" pos="-0.49 0.46 0.15" size="0.11" rgba="1 0 0 1"/>
    <site name="obj_79" pos="-0.49 0.46 0.15" size="0.11" rgba="1 0 0 1"/>
    <site name="obj_80" pos="-0.49 0.46 0.15" size="0.11" rgba="1 0 0 1"/>
    <site name="obj_81" pos="-0.49 0.46 0.15" size="0.11" rgba="1 0 0 1"/>
    <site name="obj_82" pos="-0.49 0.46 0.15" size="0.11" rgba="1 0 0 1"/>
    <site name="obj_83" pos="-0.49 0.46 0.15" size="0.11" rgba="1 0 0 1"/>
    <site name="obj_84" pos="-0.49 0.46 0.15" size="0.11" rgba="1 0 0 1"/>
    <site name="obj_85" pos="-0.49 0.46 0.15" size="0.11" rgba="1 0 0 1"/>
    <site name="obj_86" pos="-0.49 0.46 0.15" size="0.11" rgba="1 0 0 1"/>
    <site name="obj_87" pos="-0.49 0.46 0.15" size="0.11" rgba="1 0 0 1"/>
    <site name="obj_88" pos="-0.49 0.46 0.15" size="0.11" rgba="1 0 0 1"/>
    <site name="obj_89" pos="-0.49 0.46 0.15" size="0.11" rgba="1 0 0 1"/>
    <site name="obj_90" pos="-0.49 0.46 0.15" size="0.11" rgba="1 0 0 1"/>
    <site name="obj_91" pos="-0.49 0.46 0.15" size="0.11" rgba="1 0 0 1"/>
    <site name="obj_92" pos="-0.49 0.46 0.15" size="0.11" rgba="1 0 0 1"/>
    <site name="obj_93" pos="-0.49 0.46 0.15" size="0.11" rgba="1 0 0 1"/>
    <site name="obj_94" pos="-0.49 0.46 0.15" size="0.11" rgba="1 0 0 1"/>
    <site name="obj_95" pos="-0.49 0.46 0.15" size="0.11" rgba="1 0 0 1"/>
    <site name="obj_96" pos="-0.49 0.46 0.15" size="0.11" rgba="1 0 0 1"/>
    <site name="obj_97" pos="-0.49 0.46 0.15" size="0.11" rgba="1 0 0 1"/>
    <site name="obj_98" pos="-0.49 0.46 0.15" size="0.11" rgba="1 0 0 1"/>
    <site name="obj_99" pos="-0.49 0.46 0.15" size="0.11" rgba="1 0 0 1"/>
    <site name="obj_100" pos="-0.49 0.46 0.15" size="0.11" rgba="1 0 0 1"/> -->

  </worldbody>

  <actuator>
    <motor joint='ballx' ctrlrange="-1 1" ctrllimited="true" />
    <motor joint='bally' ctrlrange="-1 1" ctrllimited="true" />
    <motor joint='random_joint' ctrlrange="-1 1" ctrllimited="true" />
  </actuator>

  <keyframe>
      <key time="0" qpos="0 0 2.5 0. 0" />
  </keyframe>
</mujoco>